<robot name="robosnake">
  <link name='segment_01'>
      <inertial>
        <origin xyz="0.084 0 0" rpy="1.5708 -0 0" />
        <mass value="0.4" />
        <inertia ixx="0.00018565" ixy="0.00003467" ixz="-0.0002976" iyy="0.00034114" iyz="0.00000185" izz="0.00033012" />
      </inertial>
  </link>

  <link name='segment_02'>
      <inertial>
        <origin xyz="0.168 0 0" rpy="3.14159 -0 0" />
        <mass value="0.4" />
        <inertia ixx="0.00018565" ixy="0.00003467" ixz="-0.0002976" iyy="0.00034114" iyz="0.00000185" izz="0.00033012" />
      </inertial>
  </link>


  <joint name='joint_1' type='revolute'>
      <parent link="segment_01" />
      <child link="segment_02" />
      <origin xyz="0.007 0 0" rpy=" 0 -0 0" />
      <axis xyz="0 0 -1" />
      <limit effort="100.0" lower="-1.5708" upper="1.5708" velocity="0.2"/>
  </joint>

  <transmission name="tran1">
    <type>transmission_interface/SimpleTransmission</type>
    <joint name="joint_1">
      <hardwareInterface>EffortJointInterface</hardwareInterface>
    </joint>
    <actuator name="motor1">
      <hardwareInterface>EffortJointInterface</hardwareInterface>
      <mechanicalReduction>1</mechanicalReduction>
    </actuator>
  </transmission>
</robot>
