<robot name="robosnake">
  <link name='segment_00'/>
  <link name='segment_01'/>
  <link name='segment_02'/>
  <link name='segment_03'/>
  <link name='segment_04'/>
  <link name='segment_05'/>
  <link name='segment_06'/>
  <link name='segment_07'/>
  <link name='segment_08'/>
  <link name='segment_09'/>
  <link name='segment_10'/>

  <joint name='joint_0' type='revolute'>
      <parent link="segment_00" />
      <child link="segment_01" />
      <limit effort="17.2886" lower="-1.5708" upper="1.5708" velocity="1.6936"/>
  </joint>
  <joint name='joint_1' type='revolute'>
      <parent link="segment_01" />
      <child link="segment_02" />
      <limit effort="17.2886" lower="-1.5708" upper="1.5708" velocity="1.6936"/>
  </joint>
  <joint name='joint_2' type='revolute'>
      <parent link="segment_02" />
      <child link="segment_03" />
      <limit effort="17.2886" lower="-1.5708" upper="1.5708" velocity="1.6936"/>
  </joint>
  <joint name='joint_3' type='revolute'>
      <parent link="segment_03" />
      <child link="segment_04" />
      <limit effort="17.2886" lower="-1.5708" upper="1.5708" velocity="1.6936"/>
  </joint>
  <joint name='joint_4' type='revolute'>
      <parent link="segment_04" />
      <child link="segment_05" />
      <limit effort="17.2886" lower="-1.5708" upper="1.5708" velocity="1.6936"/>
  </joint>
  <joint name='joint_5' type='revolute'>
      <parent link="segment_05" />
      <child link="segment_06" />
      <limit effort="17.2886" lower="-1.5708" upper="1.5708" velocity="1.6936"/>
  </joint>
  <joint name='joint_6' type='revolute'>
      <parent link="segment_06" />
      <child link="segment_07" />
      <limit effort="17.2886" lower="-1.5708" upper="1.5708" velocity="1.6936"/>
  </joint>
  <joint name='joint_7' type='revolute'>
      <parent link="segment_07" />
      <child link="segment_08" />
      <limit effort="17.2886" lower="-1.5708" upper="1.5708" velocity="1.6936"/>
  </joint>
  <joint name='joint_8' type='revolute'>
      <parent link="segment_08" />
      <child link="segment_09" />
      <limit effort="17.2886" lower="-1.5708" upper="1.5708" velocity="1.6936"/>
  </joint>
  <joint name='joint_9' type='revolute'>
      <parent link="segment_09" />
      <child link="segment_10" />
      <limit effort="17.2886" lower="-1.5708" upper="1.5708" velocity="1.6936"/>
  </joint>


  <transmission name="tran0">
    <type>transmission_interface/SimpleTransmission</type>
    <joint name="joint_0">
      <hardwareInterface>EffortJointInterface</hardwareInterface>
    </joint>
    <actuator name="motor0">
      <hardwareInterface>EffortJointInterface</hardwareInterface>
      <mechanicalReduction>1</mechanicalReduction>
    </actuator>
  </transmission>
  <transmission name="tran1">
    <type>transmission_interface/SimpleTransmission</type>
    <joint name="joint_1">
      <hardwareInterface>EffortJointInterface</hardwareInterface>
    </joint>
    <actuator name="motor1">
      <hardwareInterface>EffortJointInterface</hardwareInterface>
      <mechanicalReduction>1</mechanicalReduction>
    </actuator>
  </transmission>
  <transmission name="tran2">
    <type>transmission_interface/SimpleTransmission</type>
    <joint name="joint_2">
      <hardwareInterface>EffortJointInterface</hardwareInterface>
    </joint>
    <actuator name="motor2">
      <hardwareInterface>EffortJointInterface</hardwareInterface>
      <mechanicalReduction>1</mechanicalReduction>
    </actuator>
  </transmission>
  <transmission name="tran3">
    <type>transmission_interface/SimpleTransmission</type>
    <joint name="joint_3">
      <hardwareInterface>EffortJointInterface</hardwareInterface>
    </joint>
    <actuator name="motor3">
      <hardwareInterface>EffortJointInterface</hardwareInterface>
      <mechanicalReduction>1</mechanicalReduction>
    </actuator>
  </transmission>
  <transmission name="tran4">
    <type>transmission_interface/SimpleTransmission</type>
    <joint name="joint_4">
      <hardwareInterface>EffortJointInterface</hardwareInterface>
    </joint>
    <actuator name="motor4">
      <hardwareInterface>EffortJointInterface</hardwareInterface>
      <mechanicalReduction>1</mechanicalReduction>
    </actuator>
  </transmission>
  <transmission name="tran5">
    <type>transmission_interface/SimpleTransmission</type>
    <joint name="joint_5">
      <hardwareInterface>EffortJointInterface</hardwareInterface>
    </joint>
    <actuator name="motor5">
      <hardwareInterface>EffortJointInterface</hardwareInterface>
      <mechanicalReduction>1</mechanicalReduction>
    </actuator>
  </transmission>
  <transmission name="tran6">
    <type>transmission_interface/SimpleTransmission</type>
    <joint name="joint_6">
      <hardwareInterface>EffortJointInterface</hardwareInterface>
    </joint>
    <actuator name="motor6">
      <hardwareInterface>EffortJointInterface</hardwareInterface>
      <mechanicalReduction>1</mechanicalReduction>
    </actuator>
  </transmission>
  <transmission name="tran7">
    <type>transmission_interface/SimpleTransmission</type>
    <joint name="joint_7">
      <hardwareInterface>EffortJointInterface</hardwareInterface>
    </joint>
    <actuator name="motor7">
      <hardwareInterface>EffortJointInterface</hardwareInterface>
      <mechanicalReduction>1</mechanicalReduction>
    </actuator>
  </transmission>
  <transmission name="tran8">
    <type>transmission_interface/SimpleTransmission</type>
    <joint name="joint_8">
      <hardwareInterface>EffortJointInterface</hardwareInterface>
    </joint>
    <actuator name="motor8">
      <hardwareInterface>EffortJointInterface</hardwareInterface>
      <mechanicalReduction>1</mechanicalReduction>
    </actuator>
  </transmission>
  <transmission name="tran9">
    <type>transmission_interface/SimpleTransmission</type>
    <joint name="joint_9">
      <hardwareInterface>EffortJointInterface</hardwareInterface>
    </joint>
    <actuator name="motor9">
      <hardwareInterface>EffortJointInterface</hardwareInterface>
      <mechanicalReduction>1</mechanicalReduction>
    </actuator>
  </transmission>
</robot>
